<?xml version="1.0" ?>
<!-- =================================================================================== -->
<!-- |    This document was autogenerated by xacro from /home/gaoyize/rokae_ros_ws/src/rokae_description/urdf/xMateCR7.xacro | -->
<!-- |    EDITING THIS FILE BY HAND IS NOT RECOMMENDED                                 | -->
<!-- =================================================================================== -->
<!-- xMateCR7 manipulator -->
<!--  Attention!!! inertia in the model is not correct!!! -->
<robot name="xMateCR7">
    <!-- Constants for robot dimensions -->
    <material name="black">
        <color rgba="0.0 0.0 0.0 1.0" />
    </material>
    <material name="blue">
        <color rgba="0.0 0.0 0.8 1.0" />
    </material>
    <material name="green">
        <color rgba="0.0 0.8 0.0 1.0" />
    </material>
    <material name="grey">
        <color rgba="0.2 0.2 0.2 1.0" />
    </material>
    <material name="orange">
        <color rgba="1.0 0.4235294117647059 0.0392156862745098 1.0" />
    </material>
    <material name="brown">
        <color rgba="0.8705882352941177 0.8117647058823529 0.7647058823529411 1.0" />
    </material>
    <material name="red">
        <color rgba="0.8 0.0 0.0 1.0" />
    </material>
    <material name="white">
        <color rgba="1.0 1.0 1.0 1.0" />
    </material>
    <material name="Beige">
        <color rgba="1.0 0.784 0.5765 1.0" />
    </material>
    <!-- Used for fixing robot to Gazebo 'base_link' -->
    <link name="world" />
    <joint name="fixed" type="fixed">
        <parent link="world" />
        <child link="xMateCR7_base" />
    </joint>
    <!--base-->
    <link name="xMateCR7_base">
        <visual>
            <geometry>
                <mesh filename="package://rokae_description/meshes/xMateCR7/visual/xMateCR7_base.stl" scale="0.001 0.001 0.001" />
            </geometry>
            <origin rpy="0 0 0" xyz="0.0 0.0 0.0" />
            <material name="white" />
        </visual>
        <inertial>
            <mass value="3.44074938" />
            <inertia ixx="0.01764837" ixy="0" ixz="0" iyy="0.016617391" iyz="-0.002218013" izz="1.120163944" />
            <origin rpy="0 0 0" xyz="-0.000072769597 -0.01679187012 0.2986854502" />
        </inertial>
        <collision>
            <geometry>
                <mesh filename="package://rokae_description/meshes/xMateCR7/collision/xMateCR7_base.stl" scale="0.001 0.001 0.001" />
            </geometry>
            <origin rpy="0 0 0" xyz="0.0 0.0 0.0" />
        </collision>
    </link>
    <joint name="joint1" type="revolute">
        <parent link="xMateCR7_base" />
        <child link="xMateCR7_link1" />
        <limit effort="300" lower="-3.1416" upper="3.1416" velocity="10" />
        <axis xyz="0 0 1" />
        <origin rpy="0 0 0" xyz="0 0 0" />
    </joint>
    <transmission name="tran1">
        <type>transmission_interface/SimpleTransmission</type>
        <joint name="joint1">
            <hardwareInterface>hardware_interface/PositionJointInterface</hardwareInterface>
        </joint>
        <actuator name="motor1">
            <hardwareInterface>hardware_interface/PositionJointInterface</hardwareInterface>
            <mechanicalReduction>1</mechanicalReduction>
        </actuator>
    </transmission>
    <!--link 1-->
    <link name="xMateCR7_link1">
        <visual>
            <geometry>
                <mesh filename="package://rokae_description/meshes/xMateCR7/visual/xMateCR7_link1.stl" scale="0.001 0.001 0.001" />
            </geometry>
            <origin rpy="0 0 0" xyz="0 0 0" />
            <material name="white" />
        </visual>
        <inertial>
            <mass value="3.44074938" />
            <inertia ixx="0.01764837" ixy="0" ixz="0" iyy="0.016617391" iyz="-0.002218013" izz="1.120163944" />
            <origin rpy="0 0 0" xyz="-0.000072769597 -0.01679187012 0.2986854502" />
        </inertial>
        <collision>
            <geometry>
                <mesh filename="package://rokae_description/meshes/xMateCR7/collision/xMateCR7_link1.stl" scale="0.001 0.001 0.001" />
            </geometry>
            <origin rpy="0 0 0" xyz="0 0 0" />
        </collision>
    </link>
    <joint name="joint2" type="revolute">
        <parent link="xMateCR7_link1" />
        <child link="xMateCR7_link2" />
        <limit effort="300" lower="-3.1416" upper="3.1416" velocity="10" />
        <axis xyz="0 1 0" />
        <origin rpy="0 0 0" xyz="0 0 0.296" />
    </joint>
    <transmission name="tran2">
        <type>transmission_interface/SimpleTransmission</type>
        <joint name="joint2">
            <hardwareInterface>hardware_interface/PositionJointInterface</hardwareInterface>
        </joint>
        <actuator name="motor2">
            <hardwareInterface>hardware_interface/PositionJointInterface</hardwareInterface>
            <mechanicalReduction>1</mechanicalReduction>
        </actuator>
    </transmission>
    <!--link 2-->
    <link name="xMateCR7_link2">
        <visual>
            <geometry>
                <mesh filename="package://rokae_description/meshes/xMateCR7/visual/xMateCR7_link2.stl" scale="0.001 0.001 0.001" />
            </geometry>
            <origin rpy="0 0 0" xyz="0 0 0.0" />
            <material name="white" />
        </visual>
        <inertial>
            <mass value="5.024380503" />
            <inertia ixx="0.136759927" ixy="0" ixz="0" iyy="1.747453457" iyz="-0.024189444" izz="0.012535321" />
            <origin rpy="0 0 0" xyz="-0 0.003491209523 0.2410487354" />
        </inertial>
        <collision>
            <geometry>
                <mesh filename="package://rokae_description/meshes/xMateCR7/collision/xMateCR7_link2.stl" scale="0.001 0.001 0.001" />
            </geometry>
            <origin rpy="0 0 0" xyz="0 0 0.0" />
        </collision>
    </link>
    <joint name="joint3" type="revolute">
        <parent link="xMateCR7_link2" />
        <child link="xMateCR7_link3" />
        <limit effort="300" lower="-4.9742" upper="4.9742" velocity="10" />
        <axis xyz="0 -1 0" />
        <origin rpy="0 0 0" xyz="0 0 0.49" />
    </joint>
    <transmission name="tran3">
        <type>transmission_interface/SimpleTransmission</type>
        <joint name="joint3">
            <hardwareInterface>hardware_interface/PositionJointInterface</hardwareInterface>
        </joint>
        <actuator name="motor3">
            <hardwareInterface>hardware_interface/PositionJointInterface</hardwareInterface>
            <mechanicalReduction>1</mechanicalReduction>
        </actuator>
    </transmission>
    <!--${nameofManipulator}_link 3-->
    <link name="xMateCR7_link3">
        <visual>
            <geometry>
                <mesh filename="package://rokae_description/meshes/xMateCR7/visual/xMateCR7_link3.stl" scale="0.001 0.001 0.001" />
            </geometry>
            <origin rpy="0 0 0" xyz="0 0 0" />
            <material name="white" />
        </visual>
        <inertial>
            <mass value="2.439584706" />
            <inertia ixx="0.026159338" ixy="0" ixz="0" iyy="0.024282179" iyz="-0.00615637" izz="1.11989835" />
            <origin rpy="0 0 0" xyz="0 0.023 0.097" />
        </inertial>
        <collision>
            <geometry>
                <mesh filename="package://rokae_description/meshes/xMateCR7/collision/xMateCR7_link3.stl" scale="0.001 0.001 0.001" />
            </geometry>
            <origin rpy="0 0 0" xyz="0 0 0" />
        </collision>
    </link>
    <joint name="joint4" type="revolute">
        <parent link="xMateCR7_link3" />
        <child link="xMateCR7_link4" />
        <limit effort="300" lower="-3.1416" upper="3.1416" velocity="10" />
        <!--     lower="-2.79" upper="2.79" -->
        <axis xyz="0 0 1" />
        <!--     <origin rpy="0 0 0" xyz="0.585 0.0 0.035"/> -->
        <origin rpy="0 0 0" xyz="0 0 0.36" />
    </joint>
    <transmission name="tran4">
        <type>transmission_interface/SimpleTransmission</type>
        <joint name="joint4">
            <hardwareInterface>hardware_interface/PositionJointInterface</hardwareInterface>
        </joint>
        <actuator name="motor4">
            <hardwareInterface>hardware_interface/PositionJointInterface</hardwareInterface>
            <mechanicalReduction>1</mechanicalReduction>
        </actuator>
    </transmission>
    <!--link 4-->
    <link name="xMateCR7_link4">
        <visual>
            <geometry>
                <mesh filename="package://rokae_description/meshes/xMateCR7/visual/xMateCR7_link4.stl" scale=".001 0.001 0.001" />
            </geometry>
            <origin rpy="0 0 0" xyz="0.0 0.0 0.0" />
            <material name="white" />
        </visual>
        <inertial>
            <mass value="2.439584706" />
            <inertia ixx="0.012" ixy="0" ixz="0" iyy="0.221" iyz="-0.002" izz="0.004" />
            <origin rpy="0 0 0" xyz="0 -0.020 -0.046" />
        </inertial>
        <collision>
            <geometry>
                <mesh filename="package://rokae_description/meshes/xMateCR7/collision/xMateCR7_link4.stl" scale="0.001 0.001 0.001" />
            </geometry>
            <origin rpy="0 0 0" xyz="0.0 0.0 0.0" />
        </collision>
    </link>
    <joint name="joint5" type="revolute">
        <parent link="xMateCR7_link4" />
        <child link="xMateCR7_link5" />
        <limit effort="300" lower="-3.1416" upper="3.1416" velocity="10" />
        <axis xyz="0 -1 0" />
        <origin rpy="0 0 0" xyz="0 -0.151 0" />
    </joint>
    <transmission name="tran5">
        <type>transmission_interface/SimpleTransmission</type>
        <joint name="joint5">
            <hardwareInterface>hardware_interface/PositionJointInterface</hardwareInterface>
        </joint>
        <actuator name="motor5">
            <hardwareInterface>hardware_interface/PositionJointInterface</hardwareInterface>
            <mechanicalReduction>1</mechanicalReduction>
        </actuator>
    </transmission>
    <!--link 5-->
    <link name="xMateCR7_link5">
        <visual>
            <geometry>
                <mesh filename="package://rokae_description/meshes/xMateCR7/visual/xMateCR7_link5.stl" scale="0.001 0.001 0.001" />
            </geometry>
            <origin rpy="0 0 0" xyz="0 0 0" />
            <material name="white" />
        </visual>
        <inertial>
            <mass value="2.422757896" />
            <inertia ixx="0.016" ixy="0" ixz="0" iyy="0.015" iyz="-0.002" izz="0.213" />
            <origin rpy="0 0 0" xyz="0 0.012 0.096" />
        </inertial>
        <collision>
            <geometry>
                <mesh filename="package://rokae_description/meshes/xMateCR7/collision/xMateCR7_link5.stl" scale="0.001 0.001 0.001" />
            </geometry>
            <origin rpy="0 0 0" xyz="0 0 0" />
        </collision>
    </link>
    <joint name="joint6" type="revolute">
        <parent link="xMateCR7_link5" />
        <child link="xMateCR7_link6" />
        <limit effort="300" lower="-6.1082" upper="6.1082" velocity="10" />
        <axis xyz="0 0 1" />
        <origin rpy="0.0 0.0 0" xyz="0 0 0.1265" />
    </joint>
    <transmission name="tran6">
        <type>transmission_interface/SimpleTransmission</type>
        <joint name="joint6">
            <hardwareInterface>hardware_interface/PositionJointInterface</hardwareInterface>
        </joint>
        <actuator name="motor6">
            <hardwareInterface>hardware_interface/PositionJointInterface</hardwareInterface>
            <mechanicalReduction>1</mechanicalReduction>
        </actuator>
    </transmission>
    <!--link 6-->
    <link name="xMateCR7_link6">
        <visual>
            <geometry>
                <mesh filename="package://rokae_description/meshes/xMateCR7/visual/xMateCR7_link6.stl" scale="0.001 0.001 0.001" />
            </geometry>
            <origin rpy="0 0 0" xyz="0.0 0.0 0.0" />
            <material name="white" />
        </visual>
        <inertial>
            <mass value="1.229800857" />
            <inertia ixx="0.002" ixy="-0.000000" ixz="-0.000000" iyy="0.212" iyz="-0.000000" izz="0.002" />
            <origin rpy="0 0 0" xyz="0 0.017 -0.043" />
        </inertial>
        <collision>
            <geometry>
                <mesh filename="package://rokae_description/meshes/xMateCR7/collision/xMateCR7_link6.stl" scale="0.001 0.001 0.001" />
            </geometry>
            <origin rpy="0 0 0" xyz="0.0 0.0 0.0" />
        </collision>
    </link>
    <transmission name="trans_joint1">
        <type>transmission_interface/SimpleTransmission</type>
        <joint name="joint1">
            <hardwareInterface>hardware_interface/PositionJointInterface</hardwareInterface>
        </joint>
        <actuator name="joint1_motor">
            <hardwareInterface>hardware_interface/PositionJointInterface</hardwareInterface>
            <mechanicalReduction>1</mechanicalReduction>
        </actuator>
    </transmission>
    <transmission name="trans_joint2">
        <type>transmission_interface/SimpleTransmission</type>
        <joint name="joint2">
            <hardwareInterface>hardware_interface/PositionJointInterface</hardwareInterface>
        </joint>
        <actuator name="joint2_motor">
            <hardwareInterface>hardware_interface/PositionJointInterface</hardwareInterface>
            <mechanicalReduction>1</mechanicalReduction>
        </actuator>
    </transmission>
    <transmission name="trans_joint3">
        <type>transmission_interface/SimpleTransmission</type>
        <joint name="joint3">
            <hardwareInterface>hardware_interface/PositionJointInterface</hardwareInterface>
        </joint>
        <actuator name="joint3_motor">
            <hardwareInterface>hardware_interface/PositionJointInterface</hardwareInterface>
            <mechanicalReduction>1</mechanicalReduction>
        </actuator>
    </transmission>
    <transmission name="trans_joint4">
        <type>transmission_interface/SimpleTransmission</type>
        <joint name="joint4">
            <hardwareInterface>hardware_interface/PositionJointInterface</hardwareInterface>
        </joint>
        <actuator name="joint4_motor">
            <hardwareInterface>hardware_interface/PositionJointInterface</hardwareInterface>
            <mechanicalReduction>1</mechanicalReduction>
        </actuator>
    </transmission>
    <transmission name="trans_joint5">
        <type>transmission_interface/SimpleTransmission</type>
        <joint name="joint5">
            <hardwareInterface>hardware_interface/PositionJointInterface</hardwareInterface>
        </joint>
        <actuator name="joint5_motor">
            <hardwareInterface>hardware_interface/PositionJointInterface</hardwareInterface>
            <mechanicalReduction>1</mechanicalReduction>
        </actuator>
    </transmission>
    <transmission name="trans_joint6">
        <type>transmission_interface/SimpleTransmission</type>
        <joint name="joint6">
            <hardwareInterface>hardware_interface/PositionJointInterface</hardwareInterface>
        </joint>
        <actuator name="joint6_motor">
            <hardwareInterface>hardware_interface/PositionJointInterface</hardwareInterface>
            <mechanicalReduction>1</mechanicalReduction>
        </actuator>
    </transmission>
    <gazebo>
        <plugin name="gazebo_ros_control" filename = "libgazebo_ros_control.so">
            <robotNamespace>/</robotNamespace>
        </plugin>
    </gazebo>
</robot>

